<?xml version='1.0' encoding='utf-8'?>
<robot name="snake_discrete">
  <link name="base_link">
    <visual>
      <origin xyz="0 0 0.25" rpy="0 0 0" />
      <geometry>
        <capsule length="0.5" radius="0.35" />
      </geometry>
      <material name="teal">
        <color rgba="0.24117647058823533 0.7352941176470588 0.7294117647058823 1.0" />
      </material>
    </visual>
    <collision>
      <origin xyz="0 0 0.25" rpy="0 0 0" />
      <geometry>
        <capsule length="0.5" radius="0.35" />
      </geometry>
    </collision>
    <inertial>
      <mass value="0.0294" />
      <inertia ixx="0.0152488" ixy="0" ixz="0" iyy="0.0152488" iyz="0" izz="0.0152488" />
    </inertial>
  </link>
  <link name="act0Seg0">
    <visual>
      <origin xyz="0 0 0.125" rpy="0 0 0" />
      <geometry>
        <cylinder length="0.25" radius="0.4" />
      </geometry>
      <material name="teal">
        <color rgba="0.24117647058823533 0.7352941176470588 0.7294117647058823 1.0" />
      </material>
    </visual>
    <collision>
      <origin xyz="0 0 0.125" rpy="0 0 0" />
      <geometry>
        <cylinder length="0.25" radius="0.4" />
      </geometry>
    </collision>
    <inertial>
      <mass value="0.0294" />
      <inertia ixx="0.0152488" ixy="0" ixz="0" iyy="0.0152488" iyz="0" izz="0.0152488" />
    </inertial>
  </link>
  <joint name="base_link_to_act0Seg0" type="fixed">
    <parent link="base_link" />
    <child link="act0Seg0" />
    <origin xyz="0 0 0.5" rpy="0 0 0" />
    <axis xyz="1 0 0" />
  </joint>
  <link name="act0Seg1">
    <visual>
      <origin xyz="0 0 0.25" rpy="0 0 0" />
      <geometry>
        <cylinder length="0.5" radius="0.4" />
      </geometry>
      <material name="teal">
        <color rgba="0.24117647058823533 0.7352941176470588 0.7294117647058823 1.0" />
      </material>
    </visual>
    <collision>
      <origin xyz="0 0 0.25" rpy="0 0 0" />
      <geometry>
        <cylinder length="0.5" radius="0.4" />
      </geometry>
    </collision>
    <inertial>
      <mass value="0.0294" />
      <inertia ixx="0.0152488" ixy="0" ixz="0" iyy="0.0152488" iyz="0" izz="0.0152488" />
    </inertial>
  </link>
  <joint name="act0Seg0_to_act0Seg1_ax0" type="revolute">
    <parent link="act0Seg0" />
    <child link="act0Seg1" />
    <origin xyz="0 0 0.25" rpy="0 0 0" />
    <axis xyz="1 0 0" />
    <limit lower="-3.141592" upper="3.141592" effort="100" velocity="3" />
  </joint>
  <link name="act0Seg1helper_shape">
    <visual>
      <origin xyz="0 0 0.0" rpy="0 0 0" />
      <geometry>
        <sphere radius="0.4" />
      </geometry>
      <material name="teal">
        <color rgba="0.24117647058823533 0.7352941176470588 0.7294117647058823 1.0" />
      </material>
    </visual>
    <collision>
      <origin xyz="0 0 0.0" rpy="0 0 0" />
      <geometry>
        <sphere radius="0.4" />
      </geometry>
    </collision>
    <inertial>
      <mass value="2.94e-05" />
      <inertia ixx="1.52488e-05" ixy="0.0" ixz="0.0" iyy="1.52488e-05" iyz="0.0" izz="1.52488e-05" />
    </inertial>
  </link>
  <joint name="act0Seg0_to_act0Seg1_ax0helper_shape" type="fixed">
    <parent link="act0Seg0" />
    <child link="act0Seg1helper_shape" />
    <origin xyz="0 0 0.25" rpy="0 0 0" />
    <axis xyz="1 0 0" />
  </joint>
  <link name="act0Seg2">
    <visual>
      <origin xyz="0 0 0.25" rpy="0 0 0" />
      <geometry>
        <cylinder length="0.5" radius="0.4" />
      </geometry>
      <material name="teal">
        <color rgba="0.24117647058823533 0.7352941176470588 0.7294117647058823 1.0" />
      </material>
    </visual>
    <collision>
      <origin xyz="0 0 0.25" rpy="0 0 0" />
      <geometry>
        <cylinder length="0.5" radius="0.4" />
      </geometry>
    </collision>
    <inertial>
      <mass value="0.0294" />
      <inertia ixx="0.0152488" ixy="0" ixz="0" iyy="0.0152488" iyz="0" izz="0.0152488" />
    </inertial>
  </link>
  <joint name="act0Seg1_to_act0Seg2_ax1" type="revolute">
    <parent link="act0Seg1" />
    <child link="act0Seg2" />
    <origin xyz="0 0 0.5" rpy="0 0 0" />
    <axis xyz="0 1 0" />
    <limit lower="-3.141592" upper="3.141592" effort="100" velocity="3" />
  </joint>
  <link name="act0Seg2helper_shape">
    <visual>
      <origin xyz="0 0 0.0" rpy="0 0 0" />
      <geometry>
        <sphere radius="0.4" />
      </geometry>
      <material name="teal">
        <color rgba="0.24117647058823533 0.7352941176470588 0.7294117647058823 1.0" />
      </material>
    </visual>
    <collision>
      <origin xyz="0 0 0.0" rpy="0 0 0" />
      <geometry>
        <sphere radius="0.4" />
      </geometry>
    </collision>
    <inertial>
      <mass value="2.94e-05" />
      <inertia ixx="1.52488e-05" ixy="0.0" ixz="0.0" iyy="1.52488e-05" iyz="0.0" izz="1.52488e-05" />
    </inertial>
  </link>
  <joint name="act0Seg1_to_act0Seg2_ax1helper_shape" type="fixed">
    <parent link="act0Seg1" />
    <child link="act0Seg2helper_shape" />
    <origin xyz="0 0 0.5" rpy="0 0 0" />
    <axis xyz="1 0 0" />
  </joint>
  <link name="act0Seg3">
    <visual>
      <origin xyz="0 0 0.25" rpy="0 0 0" />
      <geometry>
        <cylinder length="0.5" radius="0.4" />
      </geometry>
      <material name="teal">
        <color rgba="0.24117647058823533 0.7352941176470588 0.7294117647058823 1.0" />
      </material>
    </visual>
    <collision>
      <origin xyz="0 0 0.25" rpy="0 0 0" />
      <geometry>
        <cylinder length="0.5" radius="0.4" />
      </geometry>
    </collision>
    <inertial>
      <mass value="0.0294" />
      <inertia ixx="0.0152488" ixy="0" ixz="0" iyy="0.0152488" iyz="0" izz="0.0152488" />
    </inertial>
  </link>
  <joint name="act0Seg2_to_act0Seg3_ax0" type="revolute">
    <parent link="act0Seg2" />
    <child link="act0Seg3" />
    <origin xyz="0 0 0.5" rpy="0 0 0" />
    <axis xyz="1 0 0" />
    <limit lower="-3.141592" upper="3.141592" effort="100" velocity="3" />
  </joint>
  <link name="act0Seg3helper_shape">
    <visual>
      <origin xyz="0 0 0.0" rpy="0 0 0" />
      <geometry>
        <sphere radius="0.4" />
      </geometry>
      <material name="teal">
        <color rgba="0.24117647058823533 0.7352941176470588 0.7294117647058823 1.0" />
      </material>
    </visual>
    <collision>
      <origin xyz="0 0 0.0" rpy="0 0 0" />
      <geometry>
        <sphere radius="0.4" />
      </geometry>
    </collision>
    <inertial>
      <mass value="2.94e-05" />
      <inertia ixx="1.52488e-05" ixy="0.0" ixz="0.0" iyy="1.52488e-05" iyz="0.0" izz="1.52488e-05" />
    </inertial>
  </link>
  <joint name="act0Seg2_to_act0Seg3_ax0helper_shape" type="fixed">
    <parent link="act0Seg2" />
    <child link="act0Seg3helper_shape" />
    <origin xyz="0 0 0.5" rpy="0 0 0" />
    <axis xyz="1 0 0" />
  </joint>
  <link name="act0Seg4">
    <visual>
      <origin xyz="0 0 0.125" rpy="0 0 0" />
      <geometry>
        <cylinder length="0.25" radius="0.4" />
      </geometry>
      <material name="teal">
        <color rgba="0.24117647058823533 0.7352941176470588 0.7294117647058823 1.0" />
      </material>
    </visual>
    <collision>
      <origin xyz="0 0 0.125" rpy="0 0 0" />
      <geometry>
        <cylinder length="0.25" radius="0.4" />
      </geometry>
    </collision>
    <inertial>
      <mass value="0.0294" />
      <inertia ixx="0.0152488" ixy="0" ixz="0" iyy="0.0152488" iyz="0" izz="0.0152488" />
    </inertial>
  </link>
  <joint name="act0Seg3_to_act0Seg4_ax1" type="revolute">
    <parent link="act0Seg3" />
    <child link="act0Seg4" />
    <origin xyz="0 0 0.5" rpy="0 0 0" />
    <axis xyz="0 1 0" />
    <limit lower="-3.141592" upper="3.141592" effort="100" velocity="3" />
  </joint>
  <link name="act0Seg4helper_shape">
    <visual>
      <origin xyz="0 0 0.0" rpy="0 0 0" />
      <geometry>
        <sphere radius="0.4" />
      </geometry>
      <material name="teal">
        <color rgba="0.24117647058823533 0.7352941176470588 0.7294117647058823 1.0" />
      </material>
    </visual>
    <collision>
      <origin xyz="0 0 0.0" rpy="0 0 0" />
      <geometry>
        <sphere radius="0.4" />
      </geometry>
    </collision>
    <inertial>
      <mass value="2.94e-05" />
      <inertia ixx="1.52488e-05" ixy="0.0" ixz="0.0" iyy="1.52488e-05" iyz="0.0" izz="1.52488e-05" />
    </inertial>
  </link>
  <joint name="act0Seg3_to_act0Seg4_ax1helper_shape" type="fixed">
    <parent link="act0Seg3" />
    <child link="act0Seg4helper_shape" />
    <origin xyz="0 0 0.5" rpy="0 0 0" />
    <axis xyz="1 0 0" />
  </joint>
  <link name="act1Seg0">
    <visual>
      <origin xyz="0 0 0.125" rpy="0 0 0" />
      <geometry>
        <cylinder length="0.25" radius="0.4" />
      </geometry>
      <material name="lightblue">
        <color rgba="0.1607843137254902 0.49019607843137253 0.8862745098039215 1.0" />
      </material>
    </visual>
    <collision>
      <origin xyz="0 0 0.125" rpy="0 0 0" />
      <geometry>
        <cylinder length="0.25" radius="0.4" />
      </geometry>
    </collision>
    <inertial>
      <mass value="0.0294" />
      <inertia ixx="0.0152488" ixy="0" ixz="0" iyy="0.0152488" iyz="0" izz="0.0152488" />
    </inertial>
  </link>
  <joint name="act0Seg4_to_act1Seg0_ax1" type="fixed">
    <parent link="act0Seg4" />
    <child link="act1Seg0" />
    <origin xyz="0 0 0.25" rpy="0 0 0" />
    <axis xyz="0 1 0" />
    <limit lower="-3.141592" upper="3.141592" effort="100" velocity="3" />
  </joint>
  <link name="act1Seg1">
    <visual>
      <origin xyz="0 0 0.25" rpy="0 0 0" />
      <geometry>
        <cylinder length="0.5" radius="0.4" />
      </geometry>
      <material name="lightblue">
        <color rgba="0.1607843137254902 0.49019607843137253 0.8862745098039215 1.0" />
      </material>
    </visual>
    <collision>
      <origin xyz="0 0 0.25" rpy="0 0 0" />
      <geometry>
        <cylinder length="0.5" radius="0.4" />
      </geometry>
    </collision>
    <inertial>
      <mass value="0.0294" />
      <inertia ixx="0.0152488" ixy="0" ixz="0" iyy="0.0152488" iyz="0" izz="0.0152488" />
    </inertial>
  </link>
  <joint name="act1Seg0_to_act1Seg1_ax0" type="revolute">
    <parent link="act1Seg0" />
    <child link="act1Seg1" />
    <origin xyz="0 0 0.25" rpy="0 0 0" />
    <axis xyz="1 0 0" />
    <limit lower="-3.141592" upper="3.141592" effort="100" velocity="3" />
  </joint>
  <link name="act1Seg1helper_shape">
    <visual>
      <origin xyz="0 0 0.0" rpy="0 0 0" />
      <geometry>
        <sphere radius="0.4" />
      </geometry>
      <material name="lightblue">
        <color rgba="0.1607843137254902 0.49019607843137253 0.8862745098039215 1.0" />
      </material>
    </visual>
    <collision>
      <origin xyz="0 0 0.0" rpy="0 0 0" />
      <geometry>
        <sphere radius="0.4" />
      </geometry>
    </collision>
    <inertial>
      <mass value="2.94e-05" />
      <inertia ixx="1.52488e-05" ixy="0.0" ixz="0.0" iyy="1.52488e-05" iyz="0.0" izz="1.52488e-05" />
    </inertial>
  </link>
  <joint name="act1Seg0_to_act1Seg1_ax0helper_shape" type="fixed">
    <parent link="act1Seg0" />
    <child link="act1Seg1helper_shape" />
    <origin xyz="0 0 0.25" rpy="0 0 0" />
    <axis xyz="1 0 0" />
  </joint>
  <link name="act1Seg2">
    <visual>
      <origin xyz="0 0 0.25" rpy="0 0 0" />
      <geometry>
        <cylinder length="0.5" radius="0.4" />
      </geometry>
      <material name="lightblue">
        <color rgba="0.1607843137254902 0.49019607843137253 0.8862745098039215 1.0" />
      </material>
    </visual>
    <collision>
      <origin xyz="0 0 0.25" rpy="0 0 0" />
      <geometry>
        <cylinder length="0.5" radius="0.4" />
      </geometry>
    </collision>
    <inertial>
      <mass value="0.0294" />
      <inertia ixx="0.0152488" ixy="0" ixz="0" iyy="0.0152488" iyz="0" izz="0.0152488" />
    </inertial>
  </link>
  <joint name="act1Seg1_to_act1Seg2_ax1" type="revolute">
    <parent link="act1Seg1" />
    <child link="act1Seg2" />
    <origin xyz="0 0 0.5" rpy="0 0 0" />
    <axis xyz="0 1 0" />
    <limit lower="-3.141592" upper="3.141592" effort="100" velocity="3" />
  </joint>
  <link name="act1Seg2helper_shape">
    <visual>
      <origin xyz="0 0 0.0" rpy="0 0 0" />
      <geometry>
        <sphere radius="0.4" />
      </geometry>
      <material name="lightblue">
        <color rgba="0.1607843137254902 0.49019607843137253 0.8862745098039215 1.0" />
      </material>
    </visual>
    <collision>
      <origin xyz="0 0 0.0" rpy="0 0 0" />
      <geometry>
        <sphere radius="0.4" />
      </geometry>
    </collision>
    <inertial>
      <mass value="2.94e-05" />
      <inertia ixx="1.52488e-05" ixy="0.0" ixz="0.0" iyy="1.52488e-05" iyz="0.0" izz="1.52488e-05" />
    </inertial>
  </link>
  <joint name="act1Seg1_to_act1Seg2_ax1helper_shape" type="fixed">
    <parent link="act1Seg1" />
    <child link="act1Seg2helper_shape" />
    <origin xyz="0 0 0.5" rpy="0 0 0" />
    <axis xyz="1 0 0" />
  </joint>
  <link name="act1Seg3">
    <visual>
      <origin xyz="0 0 0.25" rpy="0 0 0" />
      <geometry>
        <cylinder length="0.5" radius="0.4" />
      </geometry>
      <material name="lightblue">
        <color rgba="0.1607843137254902 0.49019607843137253 0.8862745098039215 1.0" />
      </material>
    </visual>
    <collision>
      <origin xyz="0 0 0.25" rpy="0 0 0" />
      <geometry>
        <cylinder length="0.5" radius="0.4" />
      </geometry>
    </collision>
    <inertial>
      <mass value="0.0294" />
      <inertia ixx="0.0152488" ixy="0" ixz="0" iyy="0.0152488" iyz="0" izz="0.0152488" />
    </inertial>
  </link>
  <joint name="act1Seg2_to_act1Seg3_ax0" type="revolute">
    <parent link="act1Seg2" />
    <child link="act1Seg3" />
    <origin xyz="0 0 0.5" rpy="0 0 0" />
    <axis xyz="1 0 0" />
    <limit lower="-3.141592" upper="3.141592" effort="100" velocity="3" />
  </joint>
  <link name="act1Seg3helper_shape">
    <visual>
      <origin xyz="0 0 0.0" rpy="0 0 0" />
      <geometry>
        <sphere radius="0.4" />
      </geometry>
      <material name="lightblue">
        <color rgba="0.1607843137254902 0.49019607843137253 0.8862745098039215 1.0" />
      </material>
    </visual>
    <collision>
      <origin xyz="0 0 0.0" rpy="0 0 0" />
      <geometry>
        <sphere radius="0.4" />
      </geometry>
    </collision>
    <inertial>
      <mass value="2.94e-05" />
      <inertia ixx="1.52488e-05" ixy="0.0" ixz="0.0" iyy="1.52488e-05" iyz="0.0" izz="1.52488e-05" />
    </inertial>
  </link>
  <joint name="act1Seg2_to_act1Seg3_ax0helper_shape" type="fixed">
    <parent link="act1Seg2" />
    <child link="act1Seg3helper_shape" />
    <origin xyz="0 0 0.5" rpy="0 0 0" />
    <axis xyz="1 0 0" />
  </joint>
  <link name="act1Seg4">
    <visual>
      <origin xyz="0 0 0.125" rpy="0 0 0" />
      <geometry>
        <cylinder length="0.25" radius="0.4" />
      </geometry>
      <material name="lightblue">
        <color rgba="0.1607843137254902 0.49019607843137253 0.8862745098039215 1.0" />
      </material>
    </visual>
    <collision>
      <origin xyz="0 0 0.125" rpy="0 0 0" />
      <geometry>
        <cylinder length="0.25" radius="0.4" />
      </geometry>
    </collision>
    <inertial>
      <mass value="0.0294" />
      <inertia ixx="0.0152488" ixy="0" ixz="0" iyy="0.0152488" iyz="0" izz="0.0152488" />
    </inertial>
  </link>
  <joint name="act1Seg3_to_act1Seg4_ax1" type="revolute">
    <parent link="act1Seg3" />
    <child link="act1Seg4" />
    <origin xyz="0 0 0.5" rpy="0 0 0" />
    <axis xyz="0 1 0" />
    <limit lower="-3.141592" upper="3.141592" effort="100" velocity="3" />
  </joint>
  <link name="act1Seg4helper_shape">
    <visual>
      <origin xyz="0 0 0.0" rpy="0 0 0" />
      <geometry>
        <sphere radius="0.4" />
      </geometry>
      <material name="lightblue">
        <color rgba="0.1607843137254902 0.49019607843137253 0.8862745098039215 1.0" />
      </material>
    </visual>
    <collision>
      <origin xyz="0 0 0.0" rpy="0 0 0" />
      <geometry>
        <sphere radius="0.4" />
      </geometry>
    </collision>
    <inertial>
      <mass value="2.94e-05" />
      <inertia ixx="1.52488e-05" ixy="0.0" ixz="0.0" iyy="1.52488e-05" iyz="0.0" izz="1.52488e-05" />
    </inertial>
  </link>
  <joint name="act1Seg3_to_act1Seg4_ax1helper_shape" type="fixed">
    <parent link="act1Seg3" />
    <child link="act1Seg4helper_shape" />
    <origin xyz="0 0 0.5" rpy="0 0 0" />
    <axis xyz="1 0 0" />
  </joint>
  <link name="act2Seg0">
    <visual>
      <origin xyz="0 0 0.125" rpy="0 0 0" />
      <geometry>
        <cylinder length="0.25" radius="0.4" />
      </geometry>
      <material name="teal">
        <color rgba="0.24117647058823533 0.7352941176470588 0.7294117647058823 1.0" />
      </material>
    </visual>
    <collision>
      <origin xyz="0 0 0.125" rpy="0 0 0" />
      <geometry>
        <cylinder length="0.25" radius="0.4" />
      </geometry>
    </collision>
    <inertial>
      <mass value="0.0294" />
      <inertia ixx="0.0152488" ixy="0" ixz="0" iyy="0.0152488" iyz="0" izz="0.0152488" />
    </inertial>
  </link>
  <joint name="act1Seg4_to_act2Seg0_ax1" type="fixed">
    <parent link="act1Seg4" />
    <child link="act2Seg0" />
    <origin xyz="0 0 0.25" rpy="0 0 0" />
    <axis xyz="0 1 0" />
    <limit lower="-3.141592" upper="3.141592" effort="100" velocity="3" />
  </joint>
  <link name="act2Seg1">
    <visual>
      <origin xyz="0 0 0.25" rpy="0 0 0" />
      <geometry>
        <cylinder length="0.5" radius="0.4" />
      </geometry>
      <material name="teal">
        <color rgba="0.24117647058823533 0.7352941176470588 0.7294117647058823 1.0" />
      </material>
    </visual>
    <collision>
      <origin xyz="0 0 0.25" rpy="0 0 0" />
      <geometry>
        <cylinder length="0.5" radius="0.4" />
      </geometry>
    </collision>
    <inertial>
      <mass value="0.0294" />
      <inertia ixx="0.0152488" ixy="0" ixz="0" iyy="0.0152488" iyz="0" izz="0.0152488" />
    </inertial>
  </link>
  <joint name="act2Seg0_to_act2Seg1_ax0" type="revolute">
    <parent link="act2Seg0" />
    <child link="act2Seg1" />
    <origin xyz="0 0 0.25" rpy="0 0 0" />
    <axis xyz="1 0 0" />
    <limit lower="-3.141592" upper="3.141592" effort="100" velocity="3" />
  </joint>
  <link name="act2Seg1helper_shape">
    <visual>
      <origin xyz="0 0 0.0" rpy="0 0 0" />
      <geometry>
        <sphere radius="0.4" />
      </geometry>
      <material name="teal">
        <color rgba="0.24117647058823533 0.7352941176470588 0.7294117647058823 1.0" />
      </material>
    </visual>
    <collision>
      <origin xyz="0 0 0.0" rpy="0 0 0" />
      <geometry>
        <sphere radius="0.4" />
      </geometry>
    </collision>
    <inertial>
      <mass value="2.94e-05" />
      <inertia ixx="1.52488e-05" ixy="0.0" ixz="0.0" iyy="1.52488e-05" iyz="0.0" izz="1.52488e-05" />
    </inertial>
  </link>
  <joint name="act2Seg0_to_act2Seg1_ax0helper_shape" type="fixed">
    <parent link="act2Seg0" />
    <child link="act2Seg1helper_shape" />
    <origin xyz="0 0 0.25" rpy="0 0 0" />
    <axis xyz="1 0 0" />
  </joint>
  <link name="act2Seg2">
    <visual>
      <origin xyz="0 0 0.25" rpy="0 0 0" />
      <geometry>
        <cylinder length="0.5" radius="0.4" />
      </geometry>
      <material name="teal">
        <color rgba="0.24117647058823533 0.7352941176470588 0.7294117647058823 1.0" />
      </material>
    </visual>
    <collision>
      <origin xyz="0 0 0.25" rpy="0 0 0" />
      <geometry>
        <cylinder length="0.5" radius="0.4" />
      </geometry>
    </collision>
    <inertial>
      <mass value="0.0294" />
      <inertia ixx="0.0152488" ixy="0" ixz="0" iyy="0.0152488" iyz="0" izz="0.0152488" />
    </inertial>
  </link>
  <joint name="act2Seg1_to_act2Seg2_ax1" type="revolute">
    <parent link="act2Seg1" />
    <child link="act2Seg2" />
    <origin xyz="0 0 0.5" rpy="0 0 0" />
    <axis xyz="0 1 0" />
    <limit lower="-3.141592" upper="3.141592" effort="100" velocity="3" />
  </joint>
  <link name="act2Seg2helper_shape">
    <visual>
      <origin xyz="0 0 0.0" rpy="0 0 0" />
      <geometry>
        <sphere radius="0.4" />
      </geometry>
      <material name="teal">
        <color rgba="0.24117647058823533 0.7352941176470588 0.7294117647058823 1.0" />
      </material>
    </visual>
    <collision>
      <origin xyz="0 0 0.0" rpy="0 0 0" />
      <geometry>
        <sphere radius="0.4" />
      </geometry>
    </collision>
    <inertial>
      <mass value="2.94e-05" />
      <inertia ixx="1.52488e-05" ixy="0.0" ixz="0.0" iyy="1.52488e-05" iyz="0.0" izz="1.52488e-05" />
    </inertial>
  </link>
  <joint name="act2Seg1_to_act2Seg2_ax1helper_shape" type="fixed">
    <parent link="act2Seg1" />
    <child link="act2Seg2helper_shape" />
    <origin xyz="0 0 0.5" rpy="0 0 0" />
    <axis xyz="1 0 0" />
  </joint>
  <link name="act2Seg3">
    <visual>
      <origin xyz="0 0 0.25" rpy="0 0 0" />
      <geometry>
        <cylinder length="0.5" radius="0.4" />
      </geometry>
      <material name="teal">
        <color rgba="0.24117647058823533 0.7352941176470588 0.7294117647058823 1.0" />
      </material>
    </visual>
    <collision>
      <origin xyz="0 0 0.25" rpy="0 0 0" />
      <geometry>
        <cylinder length="0.5" radius="0.4" />
      </geometry>
    </collision>
    <inertial>
      <mass value="0.0294" />
      <inertia ixx="0.0152488" ixy="0" ixz="0" iyy="0.0152488" iyz="0" izz="0.0152488" />
    </inertial>
  </link>
  <joint name="act2Seg2_to_act2Seg3_ax0" type="revolute">
    <parent link="act2Seg2" />
    <child link="act2Seg3" />
    <origin xyz="0 0 0.5" rpy="0 0 0" />
    <axis xyz="1 0 0" />
    <limit lower="-3.141592" upper="3.141592" effort="100" velocity="3" />
  </joint>
  <link name="act2Seg3helper_shape">
    <visual>
      <origin xyz="0 0 0.0" rpy="0 0 0" />
      <geometry>
        <sphere radius="0.4" />
      </geometry>
      <material name="teal">
        <color rgba="0.24117647058823533 0.7352941176470588 0.7294117647058823 1.0" />
      </material>
    </visual>
    <collision>
      <origin xyz="0 0 0.0" rpy="0 0 0" />
      <geometry>
        <sphere radius="0.4" />
      </geometry>
    </collision>
    <inertial>
      <mass value="2.94e-05" />
      <inertia ixx="1.52488e-05" ixy="0.0" ixz="0.0" iyy="1.52488e-05" iyz="0.0" izz="1.52488e-05" />
    </inertial>
  </link>
  <joint name="act2Seg2_to_act2Seg3_ax0helper_shape" type="fixed">
    <parent link="act2Seg2" />
    <child link="act2Seg3helper_shape" />
    <origin xyz="0 0 0.5" rpy="0 0 0" />
    <axis xyz="1 0 0" />
  </joint>
  <link name="act2Seg4">
    <visual>
      <origin xyz="0 0 0.125" rpy="0 0 0" />
      <geometry>
        <cylinder length="0.25" radius="0.4" />
      </geometry>
      <material name="teal">
        <color rgba="0.24117647058823533 0.7352941176470588 0.7294117647058823 1.0" />
      </material>
    </visual>
    <collision>
      <origin xyz="0 0 0.125" rpy="0 0 0" />
      <geometry>
        <cylinder length="0.25" radius="0.4" />
      </geometry>
    </collision>
    <inertial>
      <mass value="0.0294" />
      <inertia ixx="0.0152488" ixy="0" ixz="0" iyy="0.0152488" iyz="0" izz="0.0152488" />
    </inertial>
  </link>
  <joint name="act2Seg3_to_act2Seg4_ax1" type="revolute">
    <parent link="act2Seg3" />
    <child link="act2Seg4" />
    <origin xyz="0 0 0.5" rpy="0 0 0" />
    <axis xyz="0 1 0" />
    <limit lower="-3.141592" upper="3.141592" effort="100" velocity="3" />
  </joint>
  <link name="act2Seg4helper_shape">
    <visual>
      <origin xyz="0 0 0.0" rpy="0 0 0" />
      <geometry>
        <sphere radius="0.4" />
      </geometry>
      <material name="teal">
        <color rgba="0.24117647058823533 0.7352941176470588 0.7294117647058823 1.0" />
      </material>
    </visual>
    <collision>
      <origin xyz="0 0 0.0" rpy="0 0 0" />
      <geometry>
        <sphere radius="0.4" />
      </geometry>
    </collision>
    <inertial>
      <mass value="2.94e-05" />
      <inertia ixx="1.52488e-05" ixy="0.0" ixz="0.0" iyy="1.52488e-05" iyz="0.0" izz="1.52488e-05" />
    </inertial>
  </link>
  <joint name="act2Seg3_to_act2Seg4_ax1helper_shape" type="fixed">
    <parent link="act2Seg3" />
    <child link="act2Seg4helper_shape" />
    <origin xyz="0 0 0.5" rpy="0 0 0" />
    <axis xyz="1 0 0" />
  </joint>
  <link name="act3Seg0">
    <visual>
      <origin xyz="0 0 0.125" rpy="0 0 0" />
      <geometry>
        <cylinder length="0.25" radius="0.4" />
      </geometry>
      <material name="lightblue">
        <color rgba="0.1607843137254902 0.49019607843137253 0.8862745098039215 1.0" />
      </material>
    </visual>
    <collision>
      <origin xyz="0 0 0.125" rpy="0 0 0" />
      <geometry>
        <cylinder length="0.25" radius="0.4" />
      </geometry>
    </collision>
    <inertial>
      <mass value="0.0294" />
      <inertia ixx="0.0152488" ixy="0" ixz="0" iyy="0.0152488" iyz="0" izz="0.0152488" />
    </inertial>
  </link>
  <joint name="act2Seg4_to_act3Seg0_ax1" type="fixed">
    <parent link="act2Seg4" />
    <child link="act3Seg0" />
    <origin xyz="0 0 0.25" rpy="0 0 0" />
    <axis xyz="0 1 0" />
    <limit lower="-3.141592" upper="3.141592" effort="100" velocity="3" />
  </joint>
  <link name="act3Seg1">
    <visual>
      <origin xyz="0 0 0.25" rpy="0 0 0" />
      <geometry>
        <cylinder length="0.5" radius="0.4" />
      </geometry>
      <material name="lightblue">
        <color rgba="0.1607843137254902 0.49019607843137253 0.8862745098039215 1.0" />
      </material>
    </visual>
    <collision>
      <origin xyz="0 0 0.25" rpy="0 0 0" />
      <geometry>
        <cylinder length="0.5" radius="0.4" />
      </geometry>
    </collision>
    <inertial>
      <mass value="0.0294" />
      <inertia ixx="0.0152488" ixy="0" ixz="0" iyy="0.0152488" iyz="0" izz="0.0152488" />
    </inertial>
  </link>
  <joint name="act3Seg0_to_act3Seg1_ax0" type="revolute">
    <parent link="act3Seg0" />
    <child link="act3Seg1" />
    <origin xyz="0 0 0.25" rpy="0 0 0" />
    <axis xyz="1 0 0" />
    <limit lower="-3.141592" upper="3.141592" effort="100" velocity="3" />
  </joint>
  <link name="act3Seg1helper_shape">
    <visual>
      <origin xyz="0 0 0.0" rpy="0 0 0" />
      <geometry>
        <sphere radius="0.4" />
      </geometry>
      <material name="lightblue">
        <color rgba="0.1607843137254902 0.49019607843137253 0.8862745098039215 1.0" />
      </material>
    </visual>
    <collision>
      <origin xyz="0 0 0.0" rpy="0 0 0" />
      <geometry>
        <sphere radius="0.4" />
      </geometry>
    </collision>
    <inertial>
      <mass value="2.94e-05" />
      <inertia ixx="1.52488e-05" ixy="0.0" ixz="0.0" iyy="1.52488e-05" iyz="0.0" izz="1.52488e-05" />
    </inertial>
  </link>
  <joint name="act3Seg0_to_act3Seg1_ax0helper_shape" type="fixed">
    <parent link="act3Seg0" />
    <child link="act3Seg1helper_shape" />
    <origin xyz="0 0 0.25" rpy="0 0 0" />
    <axis xyz="1 0 0" />
  </joint>
  <link name="act3Seg2">
    <visual>
      <origin xyz="0 0 0.25" rpy="0 0 0" />
      <geometry>
        <cylinder length="0.5" radius="0.4" />
      </geometry>
      <material name="lightblue">
        <color rgba="0.1607843137254902 0.49019607843137253 0.8862745098039215 1.0" />
      </material>
    </visual>
    <collision>
      <origin xyz="0 0 0.25" rpy="0 0 0" />
      <geometry>
        <cylinder length="0.5" radius="0.4" />
      </geometry>
    </collision>
    <inertial>
      <mass value="0.0294" />
      <inertia ixx="0.0152488" ixy="0" ixz="0" iyy="0.0152488" iyz="0" izz="0.0152488" />
    </inertial>
  </link>
  <joint name="act3Seg1_to_act3Seg2_ax1" type="revolute">
    <parent link="act3Seg1" />
    <child link="act3Seg2" />
    <origin xyz="0 0 0.5" rpy="0 0 0" />
    <axis xyz="0 1 0" />
    <limit lower="-3.141592" upper="3.141592" effort="100" velocity="3" />
  </joint>
  <link name="act3Seg2helper_shape">
    <visual>
      <origin xyz="0 0 0.0" rpy="0 0 0" />
      <geometry>
        <sphere radius="0.4" />
      </geometry>
      <material name="lightblue">
        <color rgba="0.1607843137254902 0.49019607843137253 0.8862745098039215 1.0" />
      </material>
    </visual>
    <collision>
      <origin xyz="0 0 0.0" rpy="0 0 0" />
      <geometry>
        <sphere radius="0.4" />
      </geometry>
    </collision>
    <inertial>
      <mass value="2.94e-05" />
      <inertia ixx="1.52488e-05" ixy="0.0" ixz="0.0" iyy="1.52488e-05" iyz="0.0" izz="1.52488e-05" />
    </inertial>
  </link>
  <joint name="act3Seg1_to_act3Seg2_ax1helper_shape" type="fixed">
    <parent link="act3Seg1" />
    <child link="act3Seg2helper_shape" />
    <origin xyz="0 0 0.5" rpy="0 0 0" />
    <axis xyz="1 0 0" />
  </joint>
  <link name="act3Seg3">
    <visual>
      <origin xyz="0 0 0.25" rpy="0 0 0" />
      <geometry>
        <cylinder length="0.5" radius="0.4" />
      </geometry>
      <material name="lightblue">
        <color rgba="0.1607843137254902 0.49019607843137253 0.8862745098039215 1.0" />
      </material>
    </visual>
    <collision>
      <origin xyz="0 0 0.25" rpy="0 0 0" />
      <geometry>
        <cylinder length="0.5" radius="0.4" />
      </geometry>
    </collision>
    <inertial>
      <mass value="0.0294" />
      <inertia ixx="0.0152488" ixy="0" ixz="0" iyy="0.0152488" iyz="0" izz="0.0152488" />
    </inertial>
  </link>
  <joint name="act3Seg2_to_act3Seg3_ax0" type="revolute">
    <parent link="act3Seg2" />
    <child link="act3Seg3" />
    <origin xyz="0 0 0.5" rpy="0 0 0" />
    <axis xyz="1 0 0" />
    <limit lower="-3.141592" upper="3.141592" effort="100" velocity="3" />
  </joint>
  <link name="act3Seg3helper_shape">
    <visual>
      <origin xyz="0 0 0.0" rpy="0 0 0" />
      <geometry>
        <sphere radius="0.4" />
      </geometry>
      <material name="lightblue">
        <color rgba="0.1607843137254902 0.49019607843137253 0.8862745098039215 1.0" />
      </material>
    </visual>
    <collision>
      <origin xyz="0 0 0.0" rpy="0 0 0" />
      <geometry>
        <sphere radius="0.4" />
      </geometry>
    </collision>
    <inertial>
      <mass value="2.94e-05" />
      <inertia ixx="1.52488e-05" ixy="0.0" ixz="0.0" iyy="1.52488e-05" iyz="0.0" izz="1.52488e-05" />
    </inertial>
  </link>
  <joint name="act3Seg2_to_act3Seg3_ax0helper_shape" type="fixed">
    <parent link="act3Seg2" />
    <child link="act3Seg3helper_shape" />
    <origin xyz="0 0 0.5" rpy="0 0 0" />
    <axis xyz="1 0 0" />
  </joint>
  <link name="act3Seg4">
    <visual>
      <origin xyz="0 0 0.125" rpy="0 0 0" />
      <geometry>
        <cylinder length="0.25" radius="0.4" />
      </geometry>
      <material name="lightblue">
        <color rgba="0.1607843137254902 0.49019607843137253 0.8862745098039215 1.0" />
      </material>
    </visual>
    <collision>
      <origin xyz="0 0 0.125" rpy="0 0 0" />
      <geometry>
        <cylinder length="0.25" radius="0.4" />
      </geometry>
    </collision>
    <inertial>
      <mass value="0.0294" />
      <inertia ixx="0.0152488" ixy="0" ixz="0" iyy="0.0152488" iyz="0" izz="0.0152488" />
    </inertial>
  </link>
  <joint name="act3Seg3_to_act3Seg4_ax1" type="revolute">
    <parent link="act3Seg3" />
    <child link="act3Seg4" />
    <origin xyz="0 0 0.5" rpy="0 0 0" />
    <axis xyz="0 1 0" />
    <limit lower="-3.141592" upper="3.141592" effort="100" velocity="3" />
  </joint>
  <link name="act3Seg4helper_shape">
    <visual>
      <origin xyz="0 0 0.0" rpy="0 0 0" />
      <geometry>
        <sphere radius="0.4" />
      </geometry>
      <material name="lightblue">
        <color rgba="0.1607843137254902 0.49019607843137253 0.8862745098039215 1.0" />
      </material>
    </visual>
    <collision>
      <origin xyz="0 0 0.0" rpy="0 0 0" />
      <geometry>
        <sphere radius="0.4" />
      </geometry>
    </collision>
    <inertial>
      <mass value="2.94e-05" />
      <inertia ixx="1.52488e-05" ixy="0.0" ixz="0.0" iyy="1.52488e-05" iyz="0.0" izz="1.52488e-05" />
    </inertial>
  </link>
  <joint name="act3Seg3_to_act3Seg4_ax1helper_shape" type="fixed">
    <parent link="act3Seg3" />
    <child link="act3Seg4helper_shape" />
    <origin xyz="0 0 0.5" rpy="0 0 0" />
    <axis xyz="1 0 0" />
  </joint>
  <link name="act4Seg0">
    <visual>
      <origin xyz="0 0 0.125" rpy="0 0 0" />
      <geometry>
        <cylinder length="0.25" radius="0.4" />
      </geometry>
      <material name="teal">
        <color rgba="0.24117647058823533 0.7352941176470588 0.7294117647058823 1.0" />
      </material>
    </visual>
    <collision>
      <origin xyz="0 0 0.125" rpy="0 0 0" />
      <geometry>
        <cylinder length="0.25" radius="0.4" />
      </geometry>
    </collision>
    <inertial>
      <mass value="0.0294" />
      <inertia ixx="0.0152488" ixy="0" ixz="0" iyy="0.0152488" iyz="0" izz="0.0152488" />
    </inertial>
  </link>
  <joint name="act3Seg4_to_act4Seg0_ax1" type="fixed">
    <parent link="act3Seg4" />
    <child link="act4Seg0" />
    <origin xyz="0 0 0.25" rpy="0 0 0" />
    <axis xyz="0 1 0" />
    <limit lower="-3.141592" upper="3.141592" effort="100" velocity="3" />
  </joint>
  <link name="act4Seg1">
    <visual>
      <origin xyz="0 0 0.25" rpy="0 0 0" />
      <geometry>
        <cylinder length="0.5" radius="0.4" />
      </geometry>
      <material name="teal">
        <color rgba="0.24117647058823533 0.7352941176470588 0.7294117647058823 1.0" />
      </material>
    </visual>
    <collision>
      <origin xyz="0 0 0.25" rpy="0 0 0" />
      <geometry>
        <cylinder length="0.5" radius="0.4" />
      </geometry>
    </collision>
    <inertial>
      <mass value="0.0294" />
      <inertia ixx="0.0152488" ixy="0" ixz="0" iyy="0.0152488" iyz="0" izz="0.0152488" />
    </inertial>
  </link>
  <joint name="act4Seg0_to_act4Seg1_ax0" type="revolute">
    <parent link="act4Seg0" />
    <child link="act4Seg1" />
    <origin xyz="0 0 0.25" rpy="0 0 0" />
    <axis xyz="1 0 0" />
    <limit lower="-3.141592" upper="3.141592" effort="100" velocity="3" />
  </joint>
  <link name="act4Seg1helper_shape">
    <visual>
      <origin xyz="0 0 0.0" rpy="0 0 0" />
      <geometry>
        <sphere radius="0.4" />
      </geometry>
      <material name="teal">
        <color rgba="0.24117647058823533 0.7352941176470588 0.7294117647058823 1.0" />
      </material>
    </visual>
    <collision>
      <origin xyz="0 0 0.0" rpy="0 0 0" />
      <geometry>
        <sphere radius="0.4" />
      </geometry>
    </collision>
    <inertial>
      <mass value="2.94e-05" />
      <inertia ixx="1.52488e-05" ixy="0.0" ixz="0.0" iyy="1.52488e-05" iyz="0.0" izz="1.52488e-05" />
    </inertial>
  </link>
  <joint name="act4Seg0_to_act4Seg1_ax0helper_shape" type="fixed">
    <parent link="act4Seg0" />
    <child link="act4Seg1helper_shape" />
    <origin xyz="0 0 0.25" rpy="0 0 0" />
    <axis xyz="1 0 0" />
  </joint>
  <link name="act4Seg2">
    <visual>
      <origin xyz="0 0 0.25" rpy="0 0 0" />
      <geometry>
        <cylinder length="0.5" radius="0.4" />
      </geometry>
      <material name="teal">
        <color rgba="0.24117647058823533 0.7352941176470588 0.7294117647058823 1.0" />
      </material>
    </visual>
    <collision>
      <origin xyz="0 0 0.25" rpy="0 0 0" />
      <geometry>
        <cylinder length="0.5" radius="0.4" />
      </geometry>
    </collision>
    <inertial>
      <mass value="0.0294" />
      <inertia ixx="0.0152488" ixy="0" ixz="0" iyy="0.0152488" iyz="0" izz="0.0152488" />
    </inertial>
  </link>
  <joint name="act4Seg1_to_act4Seg2_ax1" type="revolute">
    <parent link="act4Seg1" />
    <child link="act4Seg2" />
    <origin xyz="0 0 0.5" rpy="0 0 0" />
    <axis xyz="0 1 0" />
    <limit lower="-3.141592" upper="3.141592" effort="100" velocity="3" />
  </joint>
  <link name="act4Seg2helper_shape">
    <visual>
      <origin xyz="0 0 0.0" rpy="0 0 0" />
      <geometry>
        <sphere radius="0.4" />
      </geometry>
      <material name="teal">
        <color rgba="0.24117647058823533 0.7352941176470588 0.7294117647058823 1.0" />
      </material>
    </visual>
    <collision>
      <origin xyz="0 0 0.0" rpy="0 0 0" />
      <geometry>
        <sphere radius="0.4" />
      </geometry>
    </collision>
    <inertial>
      <mass value="2.94e-05" />
      <inertia ixx="1.52488e-05" ixy="0.0" ixz="0.0" iyy="1.52488e-05" iyz="0.0" izz="1.52488e-05" />
    </inertial>
  </link>
  <joint name="act4Seg1_to_act4Seg2_ax1helper_shape" type="fixed">
    <parent link="act4Seg1" />
    <child link="act4Seg2helper_shape" />
    <origin xyz="0 0 0.5" rpy="0 0 0" />
    <axis xyz="1 0 0" />
  </joint>
  <link name="act4Seg3">
    <visual>
      <origin xyz="0 0 0.25" rpy="0 0 0" />
      <geometry>
        <cylinder length="0.5" radius="0.4" />
      </geometry>
      <material name="teal">
        <color rgba="0.24117647058823533 0.7352941176470588 0.7294117647058823 1.0" />
      </material>
    </visual>
    <collision>
      <origin xyz="0 0 0.25" rpy="0 0 0" />
      <geometry>
        <cylinder length="0.5" radius="0.4" />
      </geometry>
    </collision>
    <inertial>
      <mass value="0.0294" />
      <inertia ixx="0.0152488" ixy="0" ixz="0" iyy="0.0152488" iyz="0" izz="0.0152488" />
    </inertial>
  </link>
  <joint name="act4Seg2_to_act4Seg3_ax0" type="revolute">
    <parent link="act4Seg2" />
    <child link="act4Seg3" />
    <origin xyz="0 0 0.5" rpy="0 0 0" />
    <axis xyz="1 0 0" />
    <limit lower="-3.141592" upper="3.141592" effort="100" velocity="3" />
  </joint>
  <link name="act4Seg3helper_shape">
    <visual>
      <origin xyz="0 0 0.0" rpy="0 0 0" />
      <geometry>
        <sphere radius="0.4" />
      </geometry>
      <material name="teal">
        <color rgba="0.24117647058823533 0.7352941176470588 0.7294117647058823 1.0" />
      </material>
    </visual>
    <collision>
      <origin xyz="0 0 0.0" rpy="0 0 0" />
      <geometry>
        <sphere radius="0.4" />
      </geometry>
    </collision>
    <inertial>
      <mass value="2.94e-05" />
      <inertia ixx="1.52488e-05" ixy="0.0" ixz="0.0" iyy="1.52488e-05" iyz="0.0" izz="1.52488e-05" />
    </inertial>
  </link>
  <joint name="act4Seg2_to_act4Seg3_ax0helper_shape" type="fixed">
    <parent link="act4Seg2" />
    <child link="act4Seg3helper_shape" />
    <origin xyz="0 0 0.5" rpy="0 0 0" />
    <axis xyz="1 0 0" />
  </joint>
  <link name="act4Seg4">
    <visual>
      <origin xyz="0 0 0.125" rpy="0 0 0" />
      <geometry>
        <cylinder length="0.25" radius="0.4" />
      </geometry>
      <material name="teal">
        <color rgba="0.24117647058823533 0.7352941176470588 0.7294117647058823 1.0" />
      </material>
    </visual>
    <collision>
      <origin xyz="0 0 0.125" rpy="0 0 0" />
      <geometry>
        <cylinder length="0.25" radius="0.4" />
      </geometry>
    </collision>
    <inertial>
      <mass value="0.0294" />
      <inertia ixx="0.0152488" ixy="0" ixz="0" iyy="0.0152488" iyz="0" izz="0.0152488" />
    </inertial>
  </link>
  <joint name="act4Seg3_to_act4Seg4_ax1" type="revolute">
    <parent link="act4Seg3" />
    <child link="act4Seg4" />
    <origin xyz="0 0 0.5" rpy="0 0 0" />
    <axis xyz="0 1 0" />
    <limit lower="-3.141592" upper="3.141592" effort="100" velocity="3" />
  </joint>
  <link name="act4Seg4helper_shape">
    <visual>
      <origin xyz="0 0 0.0" rpy="0 0 0" />
      <geometry>
        <sphere radius="0.4" />
      </geometry>
      <material name="teal">
        <color rgba="0.24117647058823533 0.7352941176470588 0.7294117647058823 1.0" />
      </material>
    </visual>
    <collision>
      <origin xyz="0 0 0.0" rpy="0 0 0" />
      <geometry>
        <sphere radius="0.4" />
      </geometry>
    </collision>
    <inertial>
      <mass value="2.94e-05" />
      <inertia ixx="1.52488e-05" ixy="0.0" ixz="0.0" iyy="1.52488e-05" iyz="0.0" izz="1.52488e-05" />
    </inertial>
  </link>
  <joint name="act4Seg3_to_act4Seg4_ax1helper_shape" type="fixed">
    <parent link="act4Seg3" />
    <child link="act4Seg4helper_shape" />
    <origin xyz="0 0 0.5" rpy="0 0 0" />
    <axis xyz="1 0 0" />
  </joint>
  <link name="act5Seg0">
    <visual>
      <origin xyz="0 0 0.125" rpy="0 0 0" />
      <geometry>
        <cylinder length="0.25" radius="0.4" />
      </geometry>
      <material name="lightblue">
        <color rgba="0.1607843137254902 0.49019607843137253 0.8862745098039215 1.0" />
      </material>
    </visual>
    <collision>
      <origin xyz="0 0 0.125" rpy="0 0 0" />
      <geometry>
        <cylinder length="0.25" radius="0.4" />
      </geometry>
    </collision>
    <inertial>
      <mass value="0.0294" />
      <inertia ixx="0.0152488" ixy="0" ixz="0" iyy="0.0152488" iyz="0" izz="0.0152488" />
    </inertial>
  </link>
  <joint name="act4Seg4_to_act5Seg0_ax1" type="fixed">
    <parent link="act4Seg4" />
    <child link="act5Seg0" />
    <origin xyz="0 0 0.25" rpy="0 0 0" />
    <axis xyz="0 1 0" />
    <limit lower="-3.141592" upper="3.141592" effort="100" velocity="3" />
  </joint>
  <link name="act5Seg1">
    <visual>
      <origin xyz="0 0 0.25" rpy="0 0 0" />
      <geometry>
        <cylinder length="0.5" radius="0.4" />
      </geometry>
      <material name="lightblue">
        <color rgba="0.1607843137254902 0.49019607843137253 0.8862745098039215 1.0" />
      </material>
    </visual>
    <collision>
      <origin xyz="0 0 0.25" rpy="0 0 0" />
      <geometry>
        <cylinder length="0.5" radius="0.4" />
      </geometry>
    </collision>
    <inertial>
      <mass value="0.0294" />
      <inertia ixx="0.0152488" ixy="0" ixz="0" iyy="0.0152488" iyz="0" izz="0.0152488" />
    </inertial>
  </link>
  <joint name="act5Seg0_to_act5Seg1_ax0" type="revolute">
    <parent link="act5Seg0" />
    <child link="act5Seg1" />
    <origin xyz="0 0 0.25" rpy="0 0 0" />
    <axis xyz="1 0 0" />
    <limit lower="-3.141592" upper="3.141592" effort="100" velocity="3" />
  </joint>
  <link name="act5Seg1helper_shape">
    <visual>
      <origin xyz="0 0 0.0" rpy="0 0 0" />
      <geometry>
        <sphere radius="0.4" />
      </geometry>
      <material name="lightblue">
        <color rgba="0.1607843137254902 0.49019607843137253 0.8862745098039215 1.0" />
      </material>
    </visual>
    <collision>
      <origin xyz="0 0 0.0" rpy="0 0 0" />
      <geometry>
        <sphere radius="0.4" />
      </geometry>
    </collision>
    <inertial>
      <mass value="2.94e-05" />
      <inertia ixx="1.52488e-05" ixy="0.0" ixz="0.0" iyy="1.52488e-05" iyz="0.0" izz="1.52488e-05" />
    </inertial>
  </link>
  <joint name="act5Seg0_to_act5Seg1_ax0helper_shape" type="fixed">
    <parent link="act5Seg0" />
    <child link="act5Seg1helper_shape" />
    <origin xyz="0 0 0.25" rpy="0 0 0" />
    <axis xyz="1 0 0" />
  </joint>
  <link name="act5Seg2">
    <visual>
      <origin xyz="0 0 0.25" rpy="0 0 0" />
      <geometry>
        <cylinder length="0.5" radius="0.4" />
      </geometry>
      <material name="lightblue">
        <color rgba="0.1607843137254902 0.49019607843137253 0.8862745098039215 1.0" />
      </material>
    </visual>
    <collision>
      <origin xyz="0 0 0.25" rpy="0 0 0" />
      <geometry>
        <cylinder length="0.5" radius="0.4" />
      </geometry>
    </collision>
    <inertial>
      <mass value="0.0294" />
      <inertia ixx="0.0152488" ixy="0" ixz="0" iyy="0.0152488" iyz="0" izz="0.0152488" />
    </inertial>
  </link>
  <joint name="act5Seg1_to_act5Seg2_ax1" type="revolute">
    <parent link="act5Seg1" />
    <child link="act5Seg2" />
    <origin xyz="0 0 0.5" rpy="0 0 0" />
    <axis xyz="0 1 0" />
    <limit lower="-3.141592" upper="3.141592" effort="100" velocity="3" />
  </joint>
  <link name="act5Seg2helper_shape">
    <visual>
      <origin xyz="0 0 0.0" rpy="0 0 0" />
      <geometry>
        <sphere radius="0.4" />
      </geometry>
      <material name="lightblue">
        <color rgba="0.1607843137254902 0.49019607843137253 0.8862745098039215 1.0" />
      </material>
    </visual>
    <collision>
      <origin xyz="0 0 0.0" rpy="0 0 0" />
      <geometry>
        <sphere radius="0.4" />
      </geometry>
    </collision>
    <inertial>
      <mass value="2.94e-05" />
      <inertia ixx="1.52488e-05" ixy="0.0" ixz="0.0" iyy="1.52488e-05" iyz="0.0" izz="1.52488e-05" />
    </inertial>
  </link>
  <joint name="act5Seg1_to_act5Seg2_ax1helper_shape" type="fixed">
    <parent link="act5Seg1" />
    <child link="act5Seg2helper_shape" />
    <origin xyz="0 0 0.5" rpy="0 0 0" />
    <axis xyz="1 0 0" />
  </joint>
  <link name="act5Seg3">
    <visual>
      <origin xyz="0 0 0.25" rpy="0 0 0" />
      <geometry>
        <cylinder length="0.5" radius="0.4" />
      </geometry>
      <material name="lightblue">
        <color rgba="0.1607843137254902 0.49019607843137253 0.8862745098039215 1.0" />
      </material>
    </visual>
    <collision>
      <origin xyz="0 0 0.25" rpy="0 0 0" />
      <geometry>
        <cylinder length="0.5" radius="0.4" />
      </geometry>
    </collision>
    <inertial>
      <mass value="0.0294" />
      <inertia ixx="0.0152488" ixy="0" ixz="0" iyy="0.0152488" iyz="0" izz="0.0152488" />
    </inertial>
  </link>
  <joint name="act5Seg2_to_act5Seg3_ax0" type="revolute">
    <parent link="act5Seg2" />
    <child link="act5Seg3" />
    <origin xyz="0 0 0.5" rpy="0 0 0" />
    <axis xyz="1 0 0" />
    <limit lower="-3.141592" upper="3.141592" effort="100" velocity="3" />
  </joint>
  <link name="act5Seg3helper_shape">
    <visual>
      <origin xyz="0 0 0.0" rpy="0 0 0" />
      <geometry>
        <sphere radius="0.4" />
      </geometry>
      <material name="lightblue">
        <color rgba="0.1607843137254902 0.49019607843137253 0.8862745098039215 1.0" />
      </material>
    </visual>
    <collision>
      <origin xyz="0 0 0.0" rpy="0 0 0" />
      <geometry>
        <sphere radius="0.4" />
      </geometry>
    </collision>
    <inertial>
      <mass value="2.94e-05" />
      <inertia ixx="1.52488e-05" ixy="0.0" ixz="0.0" iyy="1.52488e-05" iyz="0.0" izz="1.52488e-05" />
    </inertial>
  </link>
  <joint name="act5Seg2_to_act5Seg3_ax0helper_shape" type="fixed">
    <parent link="act5Seg2" />
    <child link="act5Seg3helper_shape" />
    <origin xyz="0 0 0.5" rpy="0 0 0" />
    <axis xyz="1 0 0" />
  </joint>
  <link name="act5Seg4">
    <visual>
      <origin xyz="0 0 0.125" rpy="0 0 0" />
      <geometry>
        <cylinder length="0.25" radius="0.4" />
      </geometry>
      <material name="lightblue">
        <color rgba="0.1607843137254902 0.49019607843137253 0.8862745098039215 1.0" />
      </material>
    </visual>
    <collision>
      <origin xyz="0 0 0.125" rpy="0 0 0" />
      <geometry>
        <cylinder length="0.25" radius="0.4" />
      </geometry>
    </collision>
    <inertial>
      <mass value="0.0294" />
      <inertia ixx="0.0152488" ixy="0" ixz="0" iyy="0.0152488" iyz="0" izz="0.0152488" />
    </inertial>
  </link>
  <joint name="act5Seg3_to_act5Seg4_ax1" type="revolute">
    <parent link="act5Seg3" />
    <child link="act5Seg4" />
    <origin xyz="0 0 0.5" rpy="0 0 0" />
    <axis xyz="0 1 0" />
    <limit lower="-3.141592" upper="3.141592" effort="100" velocity="3" />
  </joint>
  <link name="act5Seg4helper_shape">
    <visual>
      <origin xyz="0 0 0.0" rpy="0 0 0" />
      <geometry>
        <sphere radius="0.4" />
      </geometry>
      <material name="lightblue">
        <color rgba="0.1607843137254902 0.49019607843137253 0.8862745098039215 1.0" />
      </material>
    </visual>
    <collision>
      <origin xyz="0 0 0.0" rpy="0 0 0" />
      <geometry>
        <sphere radius="0.4" />
      </geometry>
    </collision>
    <inertial>
      <mass value="2.94e-05" />
      <inertia ixx="1.52488e-05" ixy="0.0" ixz="0.0" iyy="1.52488e-05" iyz="0.0" izz="1.52488e-05" />
    </inertial>
  </link>
  <joint name="act5Seg3_to_act5Seg4_ax1helper_shape" type="fixed">
    <parent link="act5Seg3" />
    <child link="act5Seg4helper_shape" />
    <origin xyz="0 0 0.5" rpy="0 0 0" />
    <axis xyz="1 0 0" />
  </joint>
  <link name="act6Seg0">
    <visual>
      <origin xyz="0 0 0.125" rpy="0 0 0" />
      <geometry>
        <cylinder length="0.25" radius="0.4" />
      </geometry>
      <material name="teal">
        <color rgba="0.24117647058823533 0.7352941176470588 0.7294117647058823 1.0" />
      </material>
    </visual>
    <collision>
      <origin xyz="0 0 0.125" rpy="0 0 0" />
      <geometry>
        <cylinder length="0.25" radius="0.4" />
      </geometry>
    </collision>
    <inertial>
      <mass value="0.0294" />
      <inertia ixx="0.0152488" ixy="0" ixz="0" iyy="0.0152488" iyz="0" izz="0.0152488" />
    </inertial>
  </link>
  <joint name="act5Seg4_to_act6Seg0_ax1" type="fixed">
    <parent link="act5Seg4" />
    <child link="act6Seg0" />
    <origin xyz="0 0 0.25" rpy="0 0 0" />
    <axis xyz="0 1 0" />
    <limit lower="-3.141592" upper="3.141592" effort="100" velocity="3" />
  </joint>
  <link name="act6Seg1">
    <visual>
      <origin xyz="0 0 0.25" rpy="0 0 0" />
      <geometry>
        <cylinder length="0.5" radius="0.4" />
      </geometry>
      <material name="teal">
        <color rgba="0.24117647058823533 0.7352941176470588 0.7294117647058823 1.0" />
      </material>
    </visual>
    <collision>
      <origin xyz="0 0 0.25" rpy="0 0 0" />
      <geometry>
        <cylinder length="0.5" radius="0.4" />
      </geometry>
    </collision>
    <inertial>
      <mass value="0.0294" />
      <inertia ixx="0.0152488" ixy="0" ixz="0" iyy="0.0152488" iyz="0" izz="0.0152488" />
    </inertial>
  </link>
  <joint name="act6Seg0_to_act6Seg1_ax0" type="revolute">
    <parent link="act6Seg0" />
    <child link="act6Seg1" />
    <origin xyz="0 0 0.25" rpy="0 0 0" />
    <axis xyz="1 0 0" />
    <limit lower="-3.141592" upper="3.141592" effort="100" velocity="3" />
  </joint>
  <link name="act6Seg1helper_shape">
    <visual>
      <origin xyz="0 0 0.0" rpy="0 0 0" />
      <geometry>
        <sphere radius="0.4" />
      </geometry>
      <material name="teal">
        <color rgba="0.24117647058823533 0.7352941176470588 0.7294117647058823 1.0" />
      </material>
    </visual>
    <collision>
      <origin xyz="0 0 0.0" rpy="0 0 0" />
      <geometry>
        <sphere radius="0.4" />
      </geometry>
    </collision>
    <inertial>
      <mass value="2.94e-05" />
      <inertia ixx="1.52488e-05" ixy="0.0" ixz="0.0" iyy="1.52488e-05" iyz="0.0" izz="1.52488e-05" />
    </inertial>
  </link>
  <joint name="act6Seg0_to_act6Seg1_ax0helper_shape" type="fixed">
    <parent link="act6Seg0" />
    <child link="act6Seg1helper_shape" />
    <origin xyz="0 0 0.25" rpy="0 0 0" />
    <axis xyz="1 0 0" />
  </joint>
  <link name="act6Seg2">
    <visual>
      <origin xyz="0 0 0.25" rpy="0 0 0" />
      <geometry>
        <cylinder length="0.5" radius="0.4" />
      </geometry>
      <material name="teal">
        <color rgba="0.24117647058823533 0.7352941176470588 0.7294117647058823 1.0" />
      </material>
    </visual>
    <collision>
      <origin xyz="0 0 0.25" rpy="0 0 0" />
      <geometry>
        <cylinder length="0.5" radius="0.4" />
      </geometry>
    </collision>
    <inertial>
      <mass value="0.0294" />
      <inertia ixx="0.0152488" ixy="0" ixz="0" iyy="0.0152488" iyz="0" izz="0.0152488" />
    </inertial>
  </link>
  <joint name="act6Seg1_to_act6Seg2_ax1" type="revolute">
    <parent link="act6Seg1" />
    <child link="act6Seg2" />
    <origin xyz="0 0 0.5" rpy="0 0 0" />
    <axis xyz="0 1 0" />
    <limit lower="-3.141592" upper="3.141592" effort="100" velocity="3" />
  </joint>
  <link name="act6Seg2helper_shape">
    <visual>
      <origin xyz="0 0 0.0" rpy="0 0 0" />
      <geometry>
        <sphere radius="0.4" />
      </geometry>
      <material name="teal">
        <color rgba="0.24117647058823533 0.7352941176470588 0.7294117647058823 1.0" />
      </material>
    </visual>
    <collision>
      <origin xyz="0 0 0.0" rpy="0 0 0" />
      <geometry>
        <sphere radius="0.4" />
      </geometry>
    </collision>
    <inertial>
      <mass value="2.94e-05" />
      <inertia ixx="1.52488e-05" ixy="0.0" ixz="0.0" iyy="1.52488e-05" iyz="0.0" izz="1.52488e-05" />
    </inertial>
  </link>
  <joint name="act6Seg1_to_act6Seg2_ax1helper_shape" type="fixed">
    <parent link="act6Seg1" />
    <child link="act6Seg2helper_shape" />
    <origin xyz="0 0 0.5" rpy="0 0 0" />
    <axis xyz="1 0 0" />
  </joint>
  <link name="act6Seg3">
    <visual>
      <origin xyz="0 0 0.25" rpy="0 0 0" />
      <geometry>
        <cylinder length="0.5" radius="0.4" />
      </geometry>
      <material name="teal">
        <color rgba="0.24117647058823533 0.7352941176470588 0.7294117647058823 1.0" />
      </material>
    </visual>
    <collision>
      <origin xyz="0 0 0.25" rpy="0 0 0" />
      <geometry>
        <cylinder length="0.5" radius="0.4" />
      </geometry>
    </collision>
    <inertial>
      <mass value="0.0294" />
      <inertia ixx="0.0152488" ixy="0" ixz="0" iyy="0.0152488" iyz="0" izz="0.0152488" />
    </inertial>
  </link>
  <joint name="act6Seg2_to_act6Seg3_ax0" type="revolute">
    <parent link="act6Seg2" />
    <child link="act6Seg3" />
    <origin xyz="0 0 0.5" rpy="0 0 0" />
    <axis xyz="1 0 0" />
    <limit lower="-3.141592" upper="3.141592" effort="100" velocity="3" />
  </joint>
  <link name="act6Seg3helper_shape">
    <visual>
      <origin xyz="0 0 0.0" rpy="0 0 0" />
      <geometry>
        <sphere radius="0.4" />
      </geometry>
      <material name="teal">
        <color rgba="0.24117647058823533 0.7352941176470588 0.7294117647058823 1.0" />
      </material>
    </visual>
    <collision>
      <origin xyz="0 0 0.0" rpy="0 0 0" />
      <geometry>
        <sphere radius="0.4" />
      </geometry>
    </collision>
    <inertial>
      <mass value="2.94e-05" />
      <inertia ixx="1.52488e-05" ixy="0.0" ixz="0.0" iyy="1.52488e-05" iyz="0.0" izz="1.52488e-05" />
    </inertial>
  </link>
  <joint name="act6Seg2_to_act6Seg3_ax0helper_shape" type="fixed">
    <parent link="act6Seg2" />
    <child link="act6Seg3helper_shape" />
    <origin xyz="0 0 0.5" rpy="0 0 0" />
    <axis xyz="1 0 0" />
  </joint>
  <link name="act6Seg4">
    <visual>
      <origin xyz="0 0 0.125" rpy="0 0 0" />
      <geometry>
        <cylinder length="0.25" radius="0.4" />
      </geometry>
      <material name="teal">
        <color rgba="0.24117647058823533 0.7352941176470588 0.7294117647058823 1.0" />
      </material>
    </visual>
    <collision>
      <origin xyz="0 0 0.125" rpy="0 0 0" />
      <geometry>
        <cylinder length="0.25" radius="0.4" />
      </geometry>
    </collision>
    <inertial>
      <mass value="0.0294" />
      <inertia ixx="0.0152488" ixy="0" ixz="0" iyy="0.0152488" iyz="0" izz="0.0152488" />
    </inertial>
  </link>
  <joint name="act6Seg3_to_act6Seg4_ax1" type="revolute">
    <parent link="act6Seg3" />
    <child link="act6Seg4" />
    <origin xyz="0 0 0.5" rpy="0 0 0" />
    <axis xyz="0 1 0" />
    <limit lower="-3.141592" upper="3.141592" effort="100" velocity="3" />
  </joint>
  <link name="act6Seg4helper_shape">
    <visual>
      <origin xyz="0 0 0.0" rpy="0 0 0" />
      <geometry>
        <sphere radius="0.4" />
      </geometry>
      <material name="teal">
        <color rgba="0.24117647058823533 0.7352941176470588 0.7294117647058823 1.0" />
      </material>
    </visual>
    <collision>
      <origin xyz="0 0 0.0" rpy="0 0 0" />
      <geometry>
        <sphere radius="0.4" />
      </geometry>
    </collision>
    <inertial>
      <mass value="2.94e-05" />
      <inertia ixx="1.52488e-05" ixy="0.0" ixz="0.0" iyy="1.52488e-05" iyz="0.0" izz="1.52488e-05" />
    </inertial>
  </link>
  <joint name="act6Seg3_to_act6Seg4_ax1helper_shape" type="fixed">
    <parent link="act6Seg3" />
    <child link="act6Seg4helper_shape" />
    <origin xyz="0 0 0.5" rpy="0 0 0" />
    <axis xyz="1 0 0" />
  </joint>
  <link name="act7Seg0">
    <visual>
      <origin xyz="0 0 0.125" rpy="0 0 0" />
      <geometry>
        <cylinder length="0.25" radius="0.4" />
      </geometry>
      <material name="lightblue">
        <color rgba="0.1607843137254902 0.49019607843137253 0.8862745098039215 1.0" />
      </material>
    </visual>
    <collision>
      <origin xyz="0 0 0.125" rpy="0 0 0" />
      <geometry>
        <cylinder length="0.25" radius="0.4" />
      </geometry>
    </collision>
    <inertial>
      <mass value="0.0294" />
      <inertia ixx="0.0152488" ixy="0" ixz="0" iyy="0.0152488" iyz="0" izz="0.0152488" />
    </inertial>
  </link>
  <joint name="act6Seg4_to_act7Seg0_ax1" type="fixed">
    <parent link="act6Seg4" />
    <child link="act7Seg0" />
    <origin xyz="0 0 0.25" rpy="0 0 0" />
    <axis xyz="0 1 0" />
    <limit lower="-3.141592" upper="3.141592" effort="100" velocity="3" />
  </joint>
  <link name="act7Seg1">
    <visual>
      <origin xyz="0 0 0.25" rpy="0 0 0" />
      <geometry>
        <cylinder length="0.5" radius="0.4" />
      </geometry>
      <material name="lightblue">
        <color rgba="0.1607843137254902 0.49019607843137253 0.8862745098039215 1.0" />
      </material>
    </visual>
    <collision>
      <origin xyz="0 0 0.25" rpy="0 0 0" />
      <geometry>
        <cylinder length="0.5" radius="0.4" />
      </geometry>
    </collision>
    <inertial>
      <mass value="0.0294" />
      <inertia ixx="0.0152488" ixy="0" ixz="0" iyy="0.0152488" iyz="0" izz="0.0152488" />
    </inertial>
  </link>
  <joint name="act7Seg0_to_act7Seg1_ax0" type="revolute">
    <parent link="act7Seg0" />
    <child link="act7Seg1" />
    <origin xyz="0 0 0.25" rpy="0 0 0" />
    <axis xyz="1 0 0" />
    <limit lower="-3.141592" upper="3.141592" effort="100" velocity="3" />
  </joint>
  <link name="act7Seg1helper_shape">
    <visual>
      <origin xyz="0 0 0.0" rpy="0 0 0" />
      <geometry>
        <sphere radius="0.4" />
      </geometry>
      <material name="lightblue">
        <color rgba="0.1607843137254902 0.49019607843137253 0.8862745098039215 1.0" />
      </material>
    </visual>
    <collision>
      <origin xyz="0 0 0.0" rpy="0 0 0" />
      <geometry>
        <sphere radius="0.4" />
      </geometry>
    </collision>
    <inertial>
      <mass value="2.94e-05" />
      <inertia ixx="1.52488e-05" ixy="0.0" ixz="0.0" iyy="1.52488e-05" iyz="0.0" izz="1.52488e-05" />
    </inertial>
  </link>
  <joint name="act7Seg0_to_act7Seg1_ax0helper_shape" type="fixed">
    <parent link="act7Seg0" />
    <child link="act7Seg1helper_shape" />
    <origin xyz="0 0 0.25" rpy="0 0 0" />
    <axis xyz="1 0 0" />
  </joint>
  <link name="act7Seg2">
    <visual>
      <origin xyz="0 0 0.25" rpy="0 0 0" />
      <geometry>
        <cylinder length="0.5" radius="0.4" />
      </geometry>
      <material name="lightblue">
        <color rgba="0.1607843137254902 0.49019607843137253 0.8862745098039215 1.0" />
      </material>
    </visual>
    <collision>
      <origin xyz="0 0 0.25" rpy="0 0 0" />
      <geometry>
        <cylinder length="0.5" radius="0.4" />
      </geometry>
    </collision>
    <inertial>
      <mass value="0.0294" />
      <inertia ixx="0.0152488" ixy="0" ixz="0" iyy="0.0152488" iyz="0" izz="0.0152488" />
    </inertial>
  </link>
  <joint name="act7Seg1_to_act7Seg2_ax1" type="revolute">
    <parent link="act7Seg1" />
    <child link="act7Seg2" />
    <origin xyz="0 0 0.5" rpy="0 0 0" />
    <axis xyz="0 1 0" />
    <limit lower="-3.141592" upper="3.141592" effort="100" velocity="3" />
  </joint>
  <link name="act7Seg2helper_shape">
    <visual>
      <origin xyz="0 0 0.0" rpy="0 0 0" />
      <geometry>
        <sphere radius="0.4" />
      </geometry>
      <material name="lightblue">
        <color rgba="0.1607843137254902 0.49019607843137253 0.8862745098039215 1.0" />
      </material>
    </visual>
    <collision>
      <origin xyz="0 0 0.0" rpy="0 0 0" />
      <geometry>
        <sphere radius="0.4" />
      </geometry>
    </collision>
    <inertial>
      <mass value="2.94e-05" />
      <inertia ixx="1.52488e-05" ixy="0.0" ixz="0.0" iyy="1.52488e-05" iyz="0.0" izz="1.52488e-05" />
    </inertial>
  </link>
  <joint name="act7Seg1_to_act7Seg2_ax1helper_shape" type="fixed">
    <parent link="act7Seg1" />
    <child link="act7Seg2helper_shape" />
    <origin xyz="0 0 0.5" rpy="0 0 0" />
    <axis xyz="1 0 0" />
  </joint>
  <link name="act7Seg3">
    <visual>
      <origin xyz="0 0 0.25" rpy="0 0 0" />
      <geometry>
        <cylinder length="0.5" radius="0.4" />
      </geometry>
      <material name="lightblue">
        <color rgba="0.1607843137254902 0.49019607843137253 0.8862745098039215 1.0" />
      </material>
    </visual>
    <collision>
      <origin xyz="0 0 0.25" rpy="0 0 0" />
      <geometry>
        <cylinder length="0.5" radius="0.4" />
      </geometry>
    </collision>
    <inertial>
      <mass value="0.0294" />
      <inertia ixx="0.0152488" ixy="0" ixz="0" iyy="0.0152488" iyz="0" izz="0.0152488" />
    </inertial>
  </link>
  <joint name="act7Seg2_to_act7Seg3_ax0" type="revolute">
    <parent link="act7Seg2" />
    <child link="act7Seg3" />
    <origin xyz="0 0 0.5" rpy="0 0 0" />
    <axis xyz="1 0 0" />
    <limit lower="-3.141592" upper="3.141592" effort="100" velocity="3" />
  </joint>
  <link name="act7Seg3helper_shape">
    <visual>
      <origin xyz="0 0 0.0" rpy="0 0 0" />
      <geometry>
        <sphere radius="0.4" />
      </geometry>
      <material name="lightblue">
        <color rgba="0.1607843137254902 0.49019607843137253 0.8862745098039215 1.0" />
      </material>
    </visual>
    <collision>
      <origin xyz="0 0 0.0" rpy="0 0 0" />
      <geometry>
        <sphere radius="0.4" />
      </geometry>
    </collision>
    <inertial>
      <mass value="2.94e-05" />
      <inertia ixx="1.52488e-05" ixy="0.0" ixz="0.0" iyy="1.52488e-05" iyz="0.0" izz="1.52488e-05" />
    </inertial>
  </link>
  <joint name="act7Seg2_to_act7Seg3_ax0helper_shape" type="fixed">
    <parent link="act7Seg2" />
    <child link="act7Seg3helper_shape" />
    <origin xyz="0 0 0.5" rpy="0 0 0" />
    <axis xyz="1 0 0" />
  </joint>
  <link name="act7Seg4">
    <visual>
      <origin xyz="0 0 0.125" rpy="0 0 0" />
      <geometry>
        <cylinder length="0.25" radius="0.4" />
      </geometry>
      <material name="lightblue">
        <color rgba="0.1607843137254902 0.49019607843137253 0.8862745098039215 1.0" />
      </material>
    </visual>
    <collision>
      <origin xyz="0 0 0.125" rpy="0 0 0" />
      <geometry>
        <cylinder length="0.25" radius="0.4" />
      </geometry>
    </collision>
    <inertial>
      <mass value="0.0294" />
      <inertia ixx="0.0152488" ixy="0" ixz="0" iyy="0.0152488" iyz="0" izz="0.0152488" />
    </inertial>
  </link>
  <joint name="act7Seg3_to_act7Seg4_ax1" type="revolute">
    <parent link="act7Seg3" />
    <child link="act7Seg4" />
    <origin xyz="0 0 0.5" rpy="0 0 0" />
    <axis xyz="0 1 0" />
    <limit lower="-3.141592" upper="3.141592" effort="100" velocity="3" />
  </joint>
  <link name="act7Seg4helper_shape">
    <visual>
      <origin xyz="0 0 0.0" rpy="0 0 0" />
      <geometry>
        <sphere radius="0.4" />
      </geometry>
      <material name="lightblue">
        <color rgba="0.1607843137254902 0.49019607843137253 0.8862745098039215 1.0" />
      </material>
    </visual>
    <collision>
      <origin xyz="0 0 0.0" rpy="0 0 0" />
      <geometry>
        <sphere radius="0.4" />
      </geometry>
    </collision>
    <inertial>
      <mass value="2.94e-05" />
      <inertia ixx="1.52488e-05" ixy="0.0" ixz="0.0" iyy="1.52488e-05" iyz="0.0" izz="1.52488e-05" />
    </inertial>
  </link>
  <joint name="act7Seg3_to_act7Seg4_ax1helper_shape" type="fixed">
    <parent link="act7Seg3" />
    <child link="act7Seg4helper_shape" />
    <origin xyz="0 0 0.5" rpy="0 0 0" />
    <axis xyz="1 0 0" />
  </joint>
  <link name="tip_link">
    <visual>
      <origin xyz="0 0 0.39" rpy="0 0 0" />
      <geometry>
        <sphere radius="0.39" />
      </geometry>
      <material name="lightblue">
        <color rgba="0.1607843137254902 0.49019607843137253 0.8862745098039215 1.0" />
      </material>
    </visual>
    <collision>
      <origin xyz="0 0 0.39" rpy="0 0 0" />
      <geometry>
        <sphere radius="0.39" />
      </geometry>
    </collision>
    <inertial>
      <mass value="0.0294" />
      <inertia ixx="0.0152488" ixy="0" ixz="0" iyy="0.0152488" iyz="0" izz="0.0152488" />
    </inertial>
  </link>
  <joint name="act7Seg4_to_tip_link" type="fixed">
    <parent link="act7Seg4" />
    <child link="tip_link" />
    <origin xyz="0 0 0.25" rpy="0 0 0" />
    <axis xyz="1 0 0" />
  </joint>
</robot>
